<mujoco model="orca">
  <compiler angle="radian" meshdir="meshes/" eulerseq="zyx" discardvisual="false"/>
  <option timestep="0.001"  tolerance="1e-10" solver="Newton" jacobian="dense" cone="pyramidal" gravity="0 0 -9.81">  <!--integrator="RK4"  iteration="50"-->
        <flag contact="enable" energy="enable"/>
  </option>
    <size njmax="500" nconmax="1000" />  
    <!-- <default>
        <light castshadow="false" />
        <default class="visual">
            <geom contype="0" conaffinity="0" group="1" type="mesh" euler="1.57 0 0" />
        </default>
        <default class="collision">
            <geom contype="1" conaffinity="1" friction="1.0 0.3 0.3" rgba="0.5 0.6 0.7 0"
                margin="0.001" group="0" euler="1.57 0 0" />
        </default>
        <joint damping="0.1" frictionloss="0.02" armature="0.01"/>
    </default> -->
    <visual>
        <quality shadowsize='4096'/>
        <map znear='0.05'/>
    </visual>
    <default>
        <joint limited='true'/>
        <motor ctrllimited='true'/>
        <!-- <geom  condim='4' contype="1" conaffinity="15" solref='0.001 2' friction='0.9 0.2 0.2'/> -->
        <geom  condim='4' contype="1" conaffinity="15" solref='0.001 2' friction='1.0 0.2 0.2'/>
        <equality solref='0.001 2'/>
        <default class='visualgeom'>
            <geom material='visualgeom' condim='1' contype='0' conaffinity='0'/>
        </default>
        <default class='visualgeom2'>
            <geom material='visualgeom2' condim='1' contype='0' conaffinity='0'/>
        </default>
        <default class='obstacle'>
            <geom material='obstacle' condim='3' contype='1' conaffinity='15'/>
        </default>
    </default>
    <asset>
        <texture type="skybox" builtin="gradient" rgb1="0.3 0.5 0.7" rgb2="0 0 0" width="512" height="512"/>
        <texture name="texplane" type="2d" builtin="checker" rgb1=".2 .3 .4" rgb2=".1 0.15 0.2"
            width="512" height="512" mark="cross" markrgb=".8 .8 .8"/>
        <texture name="texplane2" type="2d" builtin="checker" rgb1="1 0.3137 0.1843" rgb2="0.0 0.30196 0.38039"
            width="512" height="512" mark="cross" markrgb=".8 .8 .8"/>

        <material name="matplane" reflectance="0." texture="texplane" texrepeat="1 1" texuniform="true"/>
        <material name="matplane2" reflectance="0.1" texture="texplane2" texrepeat="1 1" texuniform="true"/>

        <material name='obstacle'  rgba='0.9 0.6 0.2 1'/>
        <material name='visualgeom'  rgba='0.5 0.9 0.2 1'/>
        <material name='visualgeom2'  rgba='0.5 0.9 0.2 1'/>

        <mesh name="base_link" file="base_link.STL" />
        <!-- <mesh name="base_link_cls" file="base_link_cls.STL" /> -->
        <mesh name="waist_yaw_link1" file="waist_yaw_link1.STL" />
        <!-- <mesh name="waist_yaw_link1_cls" file="waist_yaw_link1_cls.STL" /> -->
        <mesh name="larm_link1" file="larm_link1.STL" />
        <!-- <mesh name="larm_link1_cls" file="larm_link1_cls.STL" /> -->
        <mesh name="larm_link2" file="larm_link2.STL" />
        <!-- <mesh name="larm_link2_cls" file="larm_link2_cls.STL" /> -->
        <mesh name="larm_link3" file="larm_link3.STL" />
        <!-- <mesh name="larm_link3_cls" file="larm_link3_cls.STL" /> -->
        <mesh name="larm_link4" file="larm_link4.STL" />
        <!-- <mesh name="larm_link4_cls" file="larm_link4_cls.STL" /> -->
        <mesh name="larm_link5" file="larm_link5.STL" />
        <!-- <mesh name="larm_link5_cls" file="larm_link5_cls.STL" /> -->
        <mesh name="larm_link6" file="larm_link6.STL" />
        <!-- <mesh name="larm_link6_cls" file="larm_link6_cls.STL" /> -->
        <mesh name="rarm_link1" file="rarm_link1.STL" />
        <!-- <mesh name="rarm_link1_cls" file="rarm_link1_cls.STL" /> -->
        <mesh name="rarm_link2" file="rarm_link2.STL" />
        <!-- <mesh name="rarm_link2_cls" file="rarm_link2_cls.STL" /> -->
        <mesh name="rarm_link3" file="rarm_link3.STL" />
        <!-- <mesh name="rarm_link3_cls" file="rarm_link3_cls.STL" /> -->
        <mesh name="rarm_link4" file="rarm_link4.STL" />
        <!-- <mesh name="rarm_link4_cls" file="rarm_link4_cls.STL" /> -->
        <mesh name="rarm_link5" file="rarm_link5.STL" />
        <!-- <mesh name="rarm_link5_cls" file="rarm_link5_cls.STL" /> -->
        <mesh name="rarm_link6" file="rarm_link6.STL" />
        <!-- <mesh name="rarm_link6_cls" file="rarm_link6_cls.STL" /> -->
        <mesh name="head_link1" file="head_link1.STL" />
        <mesh name="head_link2" file="head_link2.STL" />
        <mesh name="head_link3" file="head_link3.STL" />
        <mesh name="lleg_link1" file="lleg_link1.STL" />
        <!-- <mesh name="lleg_link1_cls" file="lleg_link1_cls.STL" /> -->
        <mesh name="lleg_link2" file="lleg_link2.STL" />
        <!-- <mesh name="lleg_link2_cls" file="lleg_link2_cls.STL" /> -->
        <mesh name="lleg_link3" file="lleg_link3.STL" />
        <!-- <mesh name="lleg_link3_cls" file="lleg_link3_cls.STL" /> -->
        <mesh name="lleg_link4" file="lleg_link4.STL" />
        <!-- <mesh name="lleg_link4_cls" file="lleg_link4_cls.STL" /> -->
        <mesh name="lleg_link5" file="lleg_link5.STL" />
        <!-- <mesh name="lleg_link5_cls" file="lleg_link5_cls.STL" /> -->
        <mesh name="lleg_link6" file="lleg_link6.STL" />
        <mesh name="lleg_link6_cls" file="lleg_link6_cls.STL" />
        <mesh name="rleg_link1" file="rleg_link1.STL" />
        <!-- <mesh name="rleg_link1_cls" file="rleg_link1_cls.STL" /> -->
        <mesh name="rleg_link2" file="rleg_link2.STL" />
        <!-- <mesh name="rleg_link2_cls" file="rleg_link2_cls.STL" /> -->
        <mesh name="rleg_link3" file="rleg_link3.STL" />
        <!-- <mesh name="rleg_link3_cls" file="rleg_link3_cls.STL" /> -->
        <mesh name="rleg_link4" file="rleg_link4.STL" />
        <!-- <mesh name="rleg_link4_cls" file="rleg_link4_cls.STL" /> -->
        <mesh name="rleg_link5" file="rleg_link5.STL" />
        <!-- <mesh name="rleg_link5_cls" file="rleg_link5_cls.STL" /> -->
        <mesh name="rleg_link6" file="rleg_link6.STL" />
        <mesh name="rleg_link6_cls" file="rleg_link6_cls.STL" />

    </asset>
    <worldbody>
        <light directional="true" diffuse=".4 .4 .4" specular="0.1 0.1 0.1" pos="0 0 5.0" dir="0 0 -1" castshadow="false"/>
        <light directional="true" diffuse=".6 .6 .6" specular="0.2 0.2 0.2" pos="0 0 4" dir="0 0 -1"/>
        <geom name="ground" type="plane" size="0 0 1" pos="0.001 0 0" quat="1 0 0 0" material="matplane" condim="1" conaffinity='15'/>
        <!-- <geom name="ground" type="hfield" hfield="hf1" size="0 0 1" pos="0.001 0 0" quat="1 0 0 0" material="matplane" condim="1" conaffinity='15'/> -->
    <!-- <body name="base_link" pos="0.0 0.0 1.0">
      <joint type='slide' axis='1 0 0' limited='false' />
      <joint type='slide' axis='0 1 0' limited='false' />
      <joint type='slide' axis='0 0 1' limited="true" range="0. 0.01" />
      <joint type='ball' limited='true' />
      <site name='imu' size='0.01' pos='0.0 0 0.0'/> -->
    <body name="base_link" pos="0.0 0.0 0.85">
      <joint type='slide' axis='1 0 0' limited='false' />
      <joint type='slide' axis='0 1 0' limited='false' />
      <joint type='slide' axis='0 0 1' limited="false" />
      <joint type='ball' limited='false' />
      <site name='imu' size='0.01' pos='0.0 0 0.0'/>

        <geom type="mesh" contype="0" conaffinity="0" group="1" rgba="1 1 1 1" mesh="base_link" />
        <geom size="0.05 0.05 0.05" type="box" rgba="1 1 1 1" />
        <body name="waist_yaw_link1" pos="0 0 0.078" quat="0.5 -0.5 -0.5 0.5">
            <inertial pos="-2.46e-05 -0.195013 0.000228684" quat="0.502097 0.498176 -0.497806 0.501904" mass="11.0332" diaginertia="0.179393 0.155358 0.0654156" />
            <joint name="waist_yaw_joint" pos="0 0 0" axis="0 -1 0" limited="true" range="-1.571 1.571" damping="0.2" />
            <geom type="mesh" contype="0" conaffinity="0" group="1" rgba="1 1 1 1" mesh="waist_yaw_link1" />
            <body name="larm_link1" pos="0.134953 -0.295908 0" quat="0.454519 0.541675 0.454519 -0.541675">
                <inertial pos="0.000439855 0.0358502 7.91e-06" quat="0.519328 0.479105 -0.519788 0.480185" mass="0.576081" diaginertia="0.00059525 0.000527291 0.000441012" />
                <joint name="larm_joint1" pos="0 0 0" axis="0 1 0" limited="true" range="-2.88 2.88" damping="0.2" />
                <geom type="mesh" contype="0" conaffinity="0" group="1" rgba="1 1 1 1" mesh="larm_link1" />
                <body name="larm_link2" pos="-0.0015 0.0499987 0" quat="0.454519 -0.541675 -0.541675 -0.454519">
                    <inertial pos="-0.0256333 0.000250778 0.0157168" quat="0.546056 0.647986 -0.337561 0.409864" mass="0.235909" diaginertia="0.000523812 0.000383492 0.000280485" />
                    <joint name="larm_joint2" pos="0 0 0" axis="0 1 0" limited="true" range="-0.17 2.62" damping="0.2" />
                    <geom type="mesh" contype="0" conaffinity="0" group="1" rgba="1 1 1 1" mesh="larm_link2" />
                    <body name="larm_link3" pos="-0.0645 0 0.0200014" quat="0.707107 0 0 0.707107">
                        <inertial pos="0.000500131 0.0897007 0.00308625" quat="0.67552 0.737342 0.000778581 -0.000328019" mass="1.08737" diaginertia="0.00248891 0.00232032 0.000710521" />
                        <joint name="larm_joint3" pos="0 0 0" axis="0 1 0" limited="true" range="-2.79 2.79" damping="0.2" />
                        <geom type="mesh" contype="0" conaffinity="0" group="1" rgba="1 1 1 1" mesh="larm_link3" />
                        <body name="larm_link4" pos="0 0.1835 0" quat="0.707107 0.707107 0 0">
                            <inertial pos="0.00191171 0.0101619 -0.056078" quat="0.944356 -0.152014 0.023265 0.29076" mass="0.63159" diaginertia="0.00143401 0.00142131 0.000920924" />
                            <joint name="larm_joint4" pos="0 0 0" axis="0 1 0" limited="true" range="-1.57 1.57" damping="0.2" />
                            <geom type="mesh" contype="0" conaffinity="0" group="1" rgba="1 1 1 1" mesh="larm_link4" />
                            <body name="larm_link5" pos="0 0 -0.075" quat="0.5 -0.5 -0.5 -0.5">
                                <inertial pos="-0.0731591 0.00618732 3.44e-06" quat="-0.109346 0.691581 0.147622 0.698547" mass="0.451979" diaginertia="0.000579673 0.000574394 0.000224843" />
                                <joint name="larm_joint5" pos="0 0 0" axis="0 1 0" limited="true" range="-0.35 1.57" damping="0.2" />
                                <geom type="mesh" contype="0" conaffinity="0" group="1" rgba="1 1 1 1" mesh="larm_link5" />
                                <body name="larm_link6" pos="-0.105 0 0" quat="0.5 0.5 -0.5 0.5">
                                    <inertial pos="0.000892339 0.105968 3.11e-05" quat="0.707253 0.70692 0.00503905 0.00567331" mass="0.830189" diaginertia="0.0023087 0.00201411 0.000612016" />
                                    <joint name="larm_joint6" pos="0 0 0" axis="0 1 0" limited="true" range="-2.79 2.79" damping="0.2" />
                                    <geom type="mesh" contype="0" conaffinity="0" group="1" rgba="1 1 1 1" mesh="larm_link6" />
                                </body>
                            </body>
                        </body>
                    </body>
                </body>
            </body>
            <body name="rarm_link1" pos="-0.134953 -0.295908 0" quat="0.541675 0.454519 0.541675 -0.454519">
                <inertial pos="0.000439873 -0.0358502 7.93e-06" quat="0.479106 0.519329 -0.480184 0.519787" mass="0.576081" diaginertia="0.000595249 0.000527291 0.000441012" />
                <joint name="rarm_joint1" pos="0 0 0" axis="0 1 0" limited="true" range="-2.88 2.88" damping="0.2" />
                <geom type="mesh" contype="0" conaffinity="0" group="1" rgba="1 1 1 1" mesh="rarm_link1" />
                <body name="rarm_link2" pos="-0.0015 -0.0499987 0" quat="0.541675 -0.454519 -0.454519 -0.541675">
                    <inertial pos="-0.0256309 0.000253501 -0.015721" quat="0.337573 0.409864 -0.546117 0.64793" mass="0.235939" diaginertia="0.000523817 0.000383486 0.000280446" />
                    <joint name="rarm_joint2" pos="0 0 0" axis="0 -1 0" limited="true" range="-0.17 2.62" damping="0.2" />
                    <geom type="mesh" contype="0" conaffinity="0" group="1" rgba="1 1 1 1" mesh="rarm_link2" />
                    <body name="rarm_link3" pos="-0.0645 0 -0.0200014" quat="0.707107 0 0 0.707107">
                        <inertial pos="0.000500342 0.0897013 -0.00308666" quat="0.737338 0.675524 -0.000289164 0.000745159" mass="1.08737" diaginertia="0.00248889 0.00232032 0.000710539" />
                        <joint name="rarm_joint3" pos="0 0 0" axis="0 1 0" limited="true" range="-2.79 2.79" damping="0.2" />
                        <geom type="mesh" contype="0" conaffinity="0" group="1" rgba="1 1 1 1" mesh="rarm_link3" />
                        <body name="rarm_link4" pos="0 0.1835 0" quat="0.707107 0.707107 0 0">
                            <inertial pos="0.00190835 -0.0101584 -0.0560802" quat="0.944512 0.152026 0.023182 -0.290255" mass="0.63162" diaginertia="0.00143403 0.00142132 0.000920982" />
                            <joint name="rarm_joint4" pos="0 0 0" axis="0 1 0" limited="true" range="-1.57 1.57" damping="0.2" />
                            <geom type="mesh" contype="0" conaffinity="0" group="1" rgba="1 1 1 1" mesh="rarm_link4" />
                            <body name="rarm_link5" pos="0 0 -0.075" quat="0.5 -0.5 -0.5 -0.5">
                                <inertial pos="-0.0731591 0.00618737 -3.6e-06" quat="-0.147696 0.698558 0.109271 0.691565" mass="0.451978" diaginertia="0.000579673 0.000574398 0.00022484" />
                                <joint name="rarm_joint5" pos="0 0 0" axis="0 1 0" limited="true" range="-0.35 1.57" damping="0.2" />
                                <geom type="mesh" contype="0" conaffinity="0" group="1" rgba="1 1 1 1" mesh="rarm_link5" />
                                <body name="rarm_link6" pos="-0.105 0 0" quat="0.5 0.5 -0.5 0.5">
                                    <inertial pos="-0.000892336 0.105968 3.1e-05" quat="0.707253 0.70692 -0.00503907 -0.00567328" mass="0.830188" diaginertia="0.0023087 0.00201411 0.000612016" />
                                    <joint name="rarm_joint6" pos="0 0 0" axis="0 1 0" limited="true" range="-2.79 2.79" damping="0.2" />
                                    <geom type="mesh" contype="0" conaffinity="0" group="1" rgba="1 1 1 1" mesh="rarm_link6" />
                                </body>
                            </body>
                        </body>
                    </body>
                </body>
            </body>
            <body name="head_link1" pos="0 -0.4656 -0.0086" quat="0.499898 -0.5 -0.5 -0.500102">
                <inertial pos="0 0 0" mass="0.000534071" diaginertia="5.34e-09 5.34e-09 5.34e-09" />
                <joint name="head_joint1" pos="0 0 0" axis="1 0 0" limited="true" range="-0.349 0.349" damping="0.2" />
                <geom type="mesh" contype="0" conaffinity="0" group="1" rgba="1 1 1 1" mesh="head_link1" />
                <body name="head_link2" pos="0 0 0" quat="0.707107 6.81134e-05 -0.707107 7.25149e-11">
                    <inertial pos="0 0 0" mass="0.000534071" diaginertia="5.34e-09 5.34e-09 5.34e-09" />
                    <joint name="head_joint2" pos="0 0 0" axis="0 1 0" limited="true" range="-0.349 0.349" damping="0.2" />
                    <geom type="mesh" contype="0" conaffinity="0" group="1" rgba="1 1 1 1" mesh="head_link2" />
                    <body name="head_link3" pos="0 0 0" quat="-0.000144019 0.707107 0.000144019 0.707107">
                        <inertial pos="-0.000672526 -8.45e-05 0.0452592" quat="0.528315 0.528245 -0.469943 0.470099" mass="0.960824" diaginertia="0.00480572 0.00459539 0.00222606" />
                        <joint name="head_joint3" pos="0 0 0" axis="0 0 1" limited="true" range="-0.523 0.349" damping="0.2" />
                        <geom type="mesh" contype="0" conaffinity="0" group="1" rgba="1 1 1 1" mesh="head_link3" />
                    </body>
                </body>
            </body>
        </body>
        <body name="lleg_link1" pos="0 0.125 0">
            <inertial pos="-0.0414232 -0.00514312 -0.0912264" quat="0.580053 0.343687 0.211571 0.70757" mass="1.86152" diaginertia="0.0136536 0.011891 0.0043835" />
            <joint name="lleg_joint1" pos="0 0 0" axis="0 -1 0" limited="true" range="-1.22 1.92" damping="0.2" />
            <geom type="mesh" contype="0" conaffinity="0" group="1" rgba="1 1 1 1" mesh="lleg_link1" />
            <body name="lleg_link2" pos="0 0 -0.1415" quat="0.5 -0.5 -0.5 -0.5">
                <inertial pos="-0.00695412 -0.00602969 5.86e-06" quat="0.698555 0.715384 0.0120792 0.0100686" mass="1.30043" diaginertia="0.00295589 0.00228715 0.00165543" />
                <joint name="lleg_joint2" pos="0 0 0" axis="0 -1 0" limited="true" range="-1.57 0.26" damping="0.2" />
                <geom type="mesh" contype="0" conaffinity="0" group="1" rgba="1 1 1 1" mesh="lleg_link2" />
                <body name="lleg_link3" pos="-0.0275 0 0" quat="0.707107 0 0 0.707107">
                    <inertial pos="-0.00319346 0.118677 0.0116288" quat="0.608127 0.462735 -0.465437 0.446571" mass="3.18617" diaginertia="0.0187932 0.0182038 0.00732765" />
                    <joint name="lleg_joint3" pos="0 0 0" axis="0 1 0" limited="true" range="-2.6 0.44" damping="0.2" />
                    <geom type="mesh" contype="0" conaffinity="0" group="1" rgba="1 1 1 1" mesh="lleg_link3" />
                    <body name="lleg_link4" pos="0 0.267722 0" quat="0.707107 0.707107 0 0">
                        <inertial pos="-0.00152225 0.00361294 -0.13256" quat="0.986147 -0.0427608 0.0064375 0.160136" mass="1.83999" diaginertia="0.0108949 0.0107882 0.001806" />
                        <joint name="lleg_joint4" pos="0 0 0" axis="0 -1 0" limited="true" range="-2.093 0.614" damping="0.2" />
                        <geom type="mesh" contype="0" conaffinity="0" group="1" rgba="1 1 1 1" mesh="lleg_link4" />
                        <body name="lleg_link5" pos="0 -0.009 -0.262">
                            <inertial pos="-0.0116562 -6.36325e-09 -0.063978" quat="0.983649 -3.53338e-06 0.180095 -1.18714e-05" mass="0.815249" diaginertia="0.000848191 0.000796114 0.00064715" />
                            <joint name="lleg_joint5" pos="0 0 0" axis="0 -1 0" limited="true" range="-1.57 1.57" damping="0.2" />
                            <geom type="mesh" contype="0" conaffinity="0" group="1" rgba="1 1 1 1" mesh="lleg_link5" />
                            <body name="lleg_link6" pos="0.0105 0 -0.071">
                                <inertial pos="0.0329783 -0.00171847 -0.0558702" quat="0.0125451 0.720137 -0.0177997 0.69349" mass="0.434268" diaginertia="0.00213972 0.00201847 0.000329009" />
                                <joint name="lleg_joint6" pos="0 0 0" axis="1 0 0" limited="true" range="-0.61 0.61" damping="0.2" />
                                <geom type="mesh" contype="0" conaffinity="0" group="1" rgba="1 1 1 1" mesh="lleg_link6" />
                                <geom quat="0.500398 0.5 0.499602 0.5" type="mesh" rgba="1 1 1 1" mesh="lleg_link6_cls" />
                            </body>
                        </body>
                    </body>
                </body>
            </body>
        </body>
        <body name="rleg_link1" pos="0 -0.125 0">
            <inertial pos="-0.041423 0.0051432 -0.091227" quat="0.70756 0.211578 0.343682 0.580066" mass="1.8615" diaginertia="0.0136539 0.0118911 0.00438351" />
            <joint name="rleg_joint1" pos="0 0 0" axis="0 -1 0" limited="true" range="-1.22 1.92" damping="0.2" />
            <geom type="mesh" contype="0" conaffinity="0" group="1" rgba="1 1 1 1" mesh="rleg_link1" />
            <body name="rleg_link2" pos="0 0 -0.1415" quat="0.5 -0.5 -0.5 -0.5">
                <inertial pos="0.006046 0.0038573 -5.86e-06" quat="0.715382 0.698556 0.0100628 0.0120839" mass="1.3004" diaginertia="0.00295588 0.00228715 0.00165537" />
                <joint name="rleg_joint2" pos="0 0 0" axis="0 1 0" limited="true" range="-1.57 0.26" damping="0.2" />
                <geom type="mesh" contype="0" conaffinity="0" group="1" rgba="1 1 1 1" mesh="rleg_link2" />
                <body name="rleg_link3" pos="-0.0275 0 0" quat="0.707107 0 0 0.707107">
                    <inertial pos="-0.00319389 0.118678 0.0116297" quat="0.465451 0.446606 -0.608101 0.462722" mass="3.18629" diaginertia="0.0187938 0.0182042 0.00732793" />
                    <joint name="rleg_joint3" pos="0 0 0" axis="0 -1 0" limited="true" range="-2.6 0.44" damping="0.2" />
                    <geom type="mesh" contype="0" conaffinity="0" group="1" rgba="1 1 1 1" mesh="rleg_link3" />
                    <body name="rleg_link4" pos="0 0.267722 0" quat="0.707035 0.707179 0 0">
                        <inertial pos="-0.00152224 -0.00361294 -0.13256" quat="0.986147 0.0427608 0.00643745 -0.160137" mass="1.83999" diaginertia="0.0108949 0.0107882 0.001806" />
                        <joint name="rleg_joint4" pos="0 0 0" axis="0 -1 0" limited="true" range="-2.093 0.614" damping="0.2" />
                        <geom type="mesh" contype="0" conaffinity="0" group="1" rgba="1 1 1 1" mesh="rleg_link4" />
                        <body name="rleg_link5" pos="0 0.009 -0.262">
                            <inertial pos="-0.011656 -6.3716e-09 -0.063978" quat="0.983648 -3.53257e-06 0.180101 -1.18726e-05" mass="0.81525" diaginertia="0.000848187 0.00079611 0.000647153" />
                            <joint name="rleg_joint5" pos="0 0 0" axis="0 -1 0" limited="true" range="-1.57 1.57" damping="0.2" />
                            <geom type="mesh" contype="0" conaffinity="0" group="1" rgba="1 1 1 1" mesh="rleg_link5" />
                            <body name="rleg_link6" pos="0.0105 0 -0.071">
                                <inertial pos="0.0329973 0.0017198 -0.0558711" quat="-0.0125978 0.720138 0.0177746 0.693489" mass="0.43429" diaginertia="0.00214024 0.00201895 0.000329065" />
                                <joint name="rleg_joint6" pos="0 0 0" axis="1 0 0" limited="true" range="-0.61 0.61" damping="0.2" />
                                <geom type="mesh" contype="0" conaffinity="0" group="1" rgba="1 1 1 1" mesh="rleg_link6" />
                                <geom quat="0.500398 0.5 0.499602 0.5" type="mesh" rgba="1 1 1 1" mesh="rleg_link6_cls" />
                            </body>
                        </body>
                    </body>
                </body>
            </body>
        </body>
                </body>
    </worldbody>

  <actuator>   

      <motor name="lleg_joint1"    joint="lleg_joint1" gear="1" ctrllimited="true" ctrlrange="-150 150"/>
      <motor name="lleg_joint2"     joint="lleg_joint2" gear="1" ctrllimited="true" ctrlrange="-90 90"/>
      <motor name="lleg_joint3"      joint="lleg_joint3" gear="1" ctrllimited="true" ctrlrange="-90 90"/>
      <motor name="lleg_joint4"   joint="lleg_joint4" gear="1" ctrllimited="true" ctrlrange="-150 150"/>
      <motor name="lleg_joint5"  joint="lleg_joint5" gear="1" ctrllimited="true" ctrlrange="-60 60"/>
      <motor name="lleg_joint6"   joint="lleg_joint6" gear="1" ctrllimited="true" ctrlrange="-36 36"/>

      <motor name="rleg_joint1"    joint="rleg_joint1" gear="1" ctrllimited="true" ctrlrange="-150 150"/>
      <motor name="rleg_joint2"     joint="rleg_joint2" gear="1" ctrllimited="true" ctrlrange="-90 90"/>
      <motor name="rleg_joint3"      joint="rleg_joint3" gear="1" ctrllimited="true" ctrlrange="-90 90"/>
      <motor name="rleg_joint4"   joint="rleg_joint4" gear="1" ctrllimited="true" ctrlrange="-150 150"/>
      <motor name="rleg_joint5"  joint="rleg_joint5" gear="1" ctrllimited="true" ctrlrange="-60 60"/>
      <motor name="rleg_joint6"   joint="rleg_joint6" gear="1" ctrllimited="true" ctrlrange="-36 36"/>

      <motor name="waist_yaw_joint"  joint="waist_yaw_joint" gear="1" ctrllimited="true" ctrlrange="-36 36"/>
      <motor name="head_joint1"  joint="head_joint1" gear="1" ctrllimited="true" ctrlrange="-3 3"/>
      <motor name="head_joint2"  joint="head_joint2" gear="1" ctrllimited="true" ctrlrange="-3 3"/>
      <motor name="head_joint3"  joint="head_joint3" gear="1" ctrllimited="true" ctrlrange="-3 3"/>


      <motor name="larm_joint1"  joint="larm_joint1" gear="1" ctrllimited="true" ctrlrange="-90 90"/>
      <motor name="larm_joint2"  joint="larm_joint2" gear="1" ctrllimited="true" ctrlrange="-36 36"/>
      <motor name="larm_joint3"  joint="larm_joint3" gear="1" ctrllimited="true" ctrlrange="-36 36"/>
      <motor name="larm_joint4"  joint="larm_joint4" gear="1" ctrllimited="true" ctrlrange="-36 36"/>
      <motor name="larm_joint5"  joint="larm_joint5" gear="1" ctrllimited="true" ctrlrange="-36 36"/>
      <motor name="larm_joint6"  joint="larm_joint6" gear="1" ctrllimited="true" ctrlrange="-36 36"/>

      <motor name="rarm_joint1"  joint="rarm_joint1" gear="1" ctrllimited="true" ctrlrange="-90 90"/>
      <motor name="rarm_joint2"  joint="rarm_joint2" gear="1" ctrllimited="true" ctrlrange="-36 36"/>
      <motor name="rarm_joint3"  joint="rarm_joint3" gear="1" ctrllimited="true" ctrlrange="-36 36"/>
      <motor name="rarm_joint4"  joint="rarm_joint4" gear="1" ctrllimited="true" ctrlrange="-36 36"/>
      <motor name="rarm_joint5"  joint="rarm_joint5" gear="1" ctrllimited="true" ctrlrange="-36 36"/>
      <motor name="rarm_joint6"  joint="rarm_joint6" gear="1" ctrllimited="true" ctrlrange="-36 36"/>

  </actuator>
  <sensor>
        <framequat     name='orientation' objtype='site' objname='imu'/>
        <framepos     name='position' objtype='site' objname='imu'/>
        <gyro          name='angular-velocity'    site='imu' cutoff='34.9'/>
        <velocimeter   name='linear-velocity'     site='imu' cutoff='30'/>
        <accelerometer name='linear-acceleration' site='imu' cutoff='157'/>
        <magnetometer  name='magnetometer'        site='imu'/>

  </sensor>

</mujoco>
