<?xml version="1.0" encoding="utf-8"?>

<robot
  name="ths_t3_tpos_urdf">
  <link
    name="base_link">
    <inertial>
      <origin
        xyz="0 0 -0.0678907"
        rpy="0 0 0" />
      <mass
        value="2.2673" />
      <inertia
        ixx="0.0051098"
        ixy="-1E-07"
        ixz="1.17E-05"
        iyy="0.0034943"
        iyz="3E-07"
        izz="0.0043318" />
    </inertial>
    <visual>
      <origin
        xyz="0 0 0"
        rpy="0 0 0" />
      <geometry>
        <mesh
          filename="../meshes/base_link.STL" />
      </geometry>
      <material
        name="">
        <color
          rgba="0.75294 0.75294 0.75294 1" />
      </material>
    </visual>
    <collision>
      <origin
        xyz="0 0 0"
        rpy="0 0 0" />
      <geometry>
        <mesh
          filename="../meshes/base_link.STL" />
      </geometry>
    </collision>
  </link>
  <link
    name="left_leg_pitch_link">
    <inertial>
      <origin
        xyz="-0.0044205 0.0569084 0"
        rpy="0 0 0" />
      <mass
        value="1.0632493" />
      <inertia
        ixx="0.0013752"
        ixy="9.6E-06"
        ixz="0"
        iyy="0.0008787"
        iyz="0"
        izz="0.0010207" />
    </inertial>
    <visual>
      <origin
        xyz="0 0 0"
        rpy="0 0 0" />
      <geometry>
        <mesh
          filename="../meshes/left_leg_pitch_link.STL" />
      </geometry>
      <material
        name="">
        <color
          rgba="0.75294 0.75294 0.75294 1" />
      </material>
    </visual>
    <collision>
      <origin
        xyz="0 0 0"
        rpy="0 0 0" />
      <geometry>
        <mesh
          filename="../meshes/left_leg_pitch_link.STL" />
      </geometry>
    </collision>
  </link>
  <joint
    name="left_leg_pitch_joint"
    type="revolute">
    <origin
      xyz="0 0.058 -0.069"
      rpy="0 0 0" />
    <parent
      link="base_link" />
    <child
      link="left_leg_pitch_link" />
    <axis
      xyz="0 -1 0" />
    <limit
      lower="-1.0"
      upper="1.3"
      effort="60"
      velocity="8" />
  </joint>
  <link
    name="left_leg_roll_link">
    <inertial>
      <origin
        xyz="-0.0020336 4.4686E-08 -0.044812"
        rpy="0 0 0" />
      <mass
        value="0.25314" />
      <inertia
        ixx="0.0004723"
        ixy="0"
        ixz="-9.75E-05"
        iyy="0.0004395"
        iyz="0"
        izz="0.0001728" />
    </inertial>
    <visual>
      <origin
        xyz="0 0 0"
        rpy="0 0 0" />
      <geometry>
        <mesh
          filename="../meshes/left_leg_roll_link.STL" />
      </geometry>
      <material
        name="">
        <color
          rgba="0.75294 0.75294 0.75294 1" />
      </material>
    </visual>
    <collision>
      <origin
        xyz="0 0 0"
        rpy="0 0 0" />
      <geometry>
        <mesh
          filename="../meshes/left_leg_roll_link.STL" />
      </geometry>
    </collision>
  </link>
  <joint
    name="left_leg_roll_joint"
    type="revolute">
    <origin
      xyz="0.02225 0.062 0"
      rpy="0 0 0" />
    <parent
      link="left_leg_pitch_link" />
    <child
      link="left_leg_roll_link" />
    <axis
      xyz="-1 0 0" />
    <limit
      lower="-0.7"
      upper="0.25"
      effort="60"
      velocity="8" />
  </joint>
  <link
    name="left_leg_yaw_link">
    <inertial>
      <origin
        xyz="-3.7449E-06 -0.0017086 -0.1081898"
        rpy="0 0 0" />
      <mass
        value="2.3142785" />
      <inertia
        ixx="0.0206062"
        ixy="-5.8E-06"
        ixz="5E-07"
        iyy="0.0208882"
        iyz="-0.0003928"
        izz="0.0022527" />
    </inertial>
    <visual>
      <origin
        xyz="0 0 0"
        rpy="0 0 0" />
      <geometry>
        <mesh
          filename="../meshes/left_leg_yaw_link.STL" />
      </geometry>
      <material
        name="">
        <color
          rgba="0.75294 0.75294 0.75294 1" />
      </material>
    </visual>
    <collision>
      <origin
        xyz="0 0 0"
        rpy="0 0 0" />
      <geometry>
        <mesh
          filename="../meshes/left_leg_yaw_link.STL" />
      </geometry>
    </collision>
  </link>
  <joint
    name="left_leg_yaw_joint"
    type="revolute">
    <origin
      xyz="-0.0195 0 -0.0965"
      rpy="0 0 0" />
    <parent
      link="left_leg_roll_link" />
    <child
      link="left_leg_yaw_link" />
    <axis
      xyz="0 0 1" />
    <limit
      lower="-1.0"
      upper="1.0"
      effort="20"
      velocity="8" />
  </joint>
  <link
    name="left_leg_knee_link">
    <inertial>
      <origin
        xyz="-0.0047016 -0.0168569 -0.1552872"
        rpy="0 0 0" />
      <mass
        value="1.0351609" />
      <inertia
        ixx="0.0112796"
        ixy="-3.38E-05"
        ixz="0.0001669"
        iyy="0.0113707"
        iyz="-0.0007066"
        izz="0.0007438" />
    </inertial>
    <visual>
      <origin
        xyz="0 0 0"
        rpy="0 0 0" />
      <geometry>
        <mesh
          filename="../meshes/left_leg_knee_link.STL" />
      </geometry>
      <material
        name="">
        <color
          rgba="0.75294 0.75294 0.75294 1" />
      </material>
    </visual>
    <collision>
      <origin
        xyz="0 0 0"
        rpy="0 0 0" />
      <geometry>
        <mesh
          filename="../meshes/left_leg_knee_link.STL" />
      </geometry>
    </collision>
  </link>
  <joint
    name="left_leg_knee_joint"
    type="revolute">
    <origin
      xyz="0 0.02225 -0.2085"
      rpy="0 0 0" />
    <parent
      link="left_leg_yaw_link" />
    <child
      link="left_leg_knee_link" />
    <axis
      xyz="0 -1 0" />
    <limit
      lower="-1.8"
      upper="0.1"
      effort="60"
      velocity="8" />
  </joint>
  <link
    name="left_leg_ankle_link">
    <inertial>
      <origin
        xyz="0.0062835 -0.0009728 -0.0377861"
        rpy="0 0 0" />
      <mass
        value="0.3371252" />
      <inertia
        ixx="0.0002257"
        ixy="-1.1E-05"
        ixz="4.4E-05"
        iyy="0.0011531"
        iyz="1.24E-05"
        izz="0.0011653" />
    </inertial>
    <visual>
      <origin
        xyz="0 0 0"
        rpy="0 0 0" />
      <geometry>
        <mesh
          filename="../meshes/left_leg_ankle_link.STL" />
      </geometry>
      <material
        name="">
        <color
          rgba="0.75294 0.75294 0.75294 1" />
      </material>
    </visual>
    <collision>
      <origin
        xyz="0 0 0"
        rpy="0 0 0" />
      <geometry>
        <mesh
          filename="../meshes/left_leg_ankle_link.STL" />
      </geometry>
    </collision>
  </link>
  <joint
    name="left_leg_ankle_joint"
    type="revolute">
    <origin
      xyz="0 -0.0205 -0.373"
      rpy="0 0 0" />
    <parent
      link="left_leg_knee_link" />
    <child
      link="left_leg_ankle_link" />
    <axis
      xyz="0 1 0" />
    <limit
      lower="-0.7"
      upper="0.7"
      effort="16"
      velocity="8" />
  </joint>
  <link
    name="right_leg_pitch_link">
    <inertial>
      <origin
        xyz="-0.0044205 -0.056908 0"
        rpy="0 0 0" />
      <mass
        value="1.0632" />
      <inertia
        ixx="0.0013752"
        ixy="-9.6E-06"
        ixz="0"
        iyy="0.0008787"
        iyz="0"
        izz="0.0010207" />
    </inertial>
    <visual>
      <origin
        xyz="0 0 0"
        rpy="0 0 0" />
      <geometry>
        <mesh
          filename="../meshes/right_leg_pitch_link.STL" />
      </geometry>
      <material
        name="">
        <color
          rgba="0.75294 0.75294 0.75294 1" />
      </material>
    </visual>
    <collision>
      <origin
        xyz="0 0 0"
        rpy="0 0 0" />
      <geometry>
        <mesh
          filename="../meshes/right_leg_pitch_link.STL" />
      </geometry>
    </collision>
  </link>
  <joint
    name="right_leg_pitch_joint"
    type="revolute">
    <origin
      xyz="0 -0.058 -0.069"
      rpy="0 0 0" />
    <parent
      link="base_link" />
    <child
      link="right_leg_pitch_link" />
    <axis
      xyz="0 1 0" />
    <limit
      lower="-1.3"
      upper="1.0"
      effort="60"
      velocity="8" />
  </joint>
  <link
    name="right_leg_roll_link">
    <inertial>
      <origin
        xyz="-0.0020336 4.4686E-08 -0.044812"
        rpy="0 0 0" />
      <mass
        value="0.25314" />
      <inertia
        ixx="0.0004723"
        ixy="0"
        ixz="-9.75E-05"
        iyy="0.0004395"
        iyz="0"
        izz="0.0001728" />
    </inertial>
    <visual>
      <origin
        xyz="0 0 0"
        rpy="0 0 0" />
      <geometry>
        <mesh
          filename="../meshes/right_leg_roll_link.STL" />
      </geometry>
      <material
        name="">
        <color
          rgba="0.75294 0.75294 0.75294 1" />
      </material>
    </visual>
    <collision>
      <origin
        xyz="0 0 0"
        rpy="0 0 0" />
      <geometry>
        <mesh
          filename="../meshes/right_leg_roll_link.STL" />
      </geometry>
    </collision>
  </link>
  <joint
    name="right_leg_roll_joint"
    type="revolute">
    <origin
      xyz="0.02225 -0.062 0"
      rpy="0 0 0" />
    <parent
      link="right_leg_pitch_link" />
    <child
      link="right_leg_roll_link" />
    <axis
      xyz="-1 0 0" />
    <limit
      lower="-0.25"
      upper="0.7"
      effort="60"
      velocity="8" />
  </joint>
  <link
    name="right_leg_yaw_link">
    <inertial>
      <origin
        xyz="3.6E-06 0.0017086 -0.1081898"
        rpy="0 0 0" />
      <mass
        value="2.3142785" />
      <inertia
        ixx="0.0206062"
        ixy="-5.8E-06"
        ixz="-5E-07"
        iyy="0.0208882"
        iyz="0.0003928"
        izz="0.0022527" />
    </inertial>
    <visual>
      <origin
        xyz="0 0 0"
        rpy="0 0 0" />
      <geometry>
        <mesh
          filename="../meshes/right_leg_yaw_link.STL" />
      </geometry>
      <material
        name="">
        <color
          rgba="0.75294 0.75294 0.75294 1" />
      </material>
    </visual>
    <collision>
      <origin
        xyz="0 0 0"
        rpy="0 0 0" />
      <geometry>
        <mesh
          filename="../meshes/right_leg_yaw_link.STL" />
      </geometry>
    </collision>
  </link>
  <joint
    name="right_leg_yaw_joint"
    type="revolute">
    <origin
      xyz="-0.0195 0 -0.0965"
      rpy="0 0 0" />
    <parent
      link="right_leg_roll_link" />
    <child
      link="right_leg_yaw_link" />
    <axis
      xyz="0 0 1" />
    <limit
      lower="-1.0"
      upper="1.0"
      effort="20"
      velocity="8" />
  </joint>
  <link
    name="right_leg_knee_link">
    <inertial>
      <origin
        xyz="-0.0045301 0.016859 -0.15523"
        rpy="0 0 0" />
      <mass
        value="1.0351609" />
      <inertia
        ixx="0.0112726"
        ixy="2.8E-05"
        ixz="0.0001857"
        iyy="0.0113588"
        iyz="0.0007043"
        izz="0.0007385" />
    </inertial>
    <visual>
      <origin
        xyz="0 0 0"
        rpy="0 0 0" />
      <geometry>
        <mesh
          filename="../meshes/right_leg_knee_link.STL" />
      </geometry>
      <material
        name="">
        <color
          rgba="0.75294 0.75294 0.75294 1" />
      </material>
    </visual>
    <collision>
      <origin
        xyz="0 0 0"
        rpy="0 0 0" />
      <geometry>
        <mesh
          filename="../meshes/right_leg_knee_link.STL" />
      </geometry>
    </collision>
  </link>
  <joint
    name="right_leg_knee_joint"
    type="revolute">
    <origin
      xyz="0 -0.02225 -0.2085"
      rpy="0 0 0" />
    <parent
      link="right_leg_yaw_link" />
    <child
      link="right_leg_knee_link" />
    <axis
      xyz="0 1 0" />
    <limit
      lower="-0.1"
      upper="1.8"
      effort="60"
      velocity="8" />
  </joint>
  <link
    name="right_leg_ankle_link">
    <inertial>
      <origin
        xyz="0.0062835 0.00097277 -0.037786"
        rpy="0 0 0" />
      <mass
        value="0.3371252" />
      <inertia
        ixx="0.0002257"
        ixy="1.1E-05"
        ixz="4.4E-05"
        iyy="0.0011531"
        iyz="-1.24E-05"
        izz="0.0011653" />
    </inertial>
    <visual>
      <origin
        xyz="0 0 0"
        rpy="0 0 0" />
      <geometry>
        <mesh
          filename="../meshes/right_leg_ankle_link.STL" />
      </geometry>
      <material
        name="">
        <color
          rgba="0.75294 0.75294 0.75294 1" />
      </material>
    </visual>
    <collision>
      <origin
        xyz="0 0 0"
        rpy="0 0 0" />
      <geometry>
        <mesh
          filename="../meshes/right_leg_ankle_link.STL" />
      </geometry>
    </collision>
  </link>
  <joint
    name="right_leg_ankle_joint"
    type="revolute">
    <origin
      xyz="0 0.0205 -0.373"
      rpy="0 0 0" />
    <parent
      link="right_leg_knee_link" />
    <child
      link="right_leg_ankle_link" />
    <axis
      xyz="0 -1 0" />
    <limit
      lower="-0.7"
      upper="0.7"
      effort="16"
      velocity="8" />
  </joint>
  <link
    name="body_m1_link">
    <inertial>
      <origin
        xyz="0.0004409 1.84E-05 0.1825833"
        rpy="0 0 0" />
      <mass
        value="5.9707712" />
      <inertia
        ixx="0.0871898"
        ixy="1.12E-05"
        ixz="-0.0003474"
        iyy="0.0731863"
        iyz="-0.0001528"
        izz="0.0226131" />
    </inertial>
    <visual>
      <origin
        xyz="0 0 0"
        rpy="0 0 0" />
      <geometry>
        <mesh
          filename="../meshes/body_m1_link.STL" />
      </geometry>
      <material
        name="">
        <color
          rgba="0.75294 0.75294 0.75294 1" />
      </material>
    </visual>
    <collision>
      <origin
        xyz="0 0 0"
        rpy="0 0 0" />
      <geometry>
        <mesh
          filename="../meshes/body_m1_link.STL" />
      </geometry>
    </collision>
  </link>
  <joint
    name="body_m1_joint"
    type="revolute">
    <origin
      xyz="0 0 0.008"
      rpy="0 0 0" />
    <parent
      link="base_link" />
    <child
      link="body_m1_link" />
    <axis
      xyz="0 0 -1" />
    <limit
      lower="-1.0"
      upper="1.0"
      effort="20"
      velocity="8" />
  </joint>
  <link
    name="head_pitch_link">
    <inertial>
      <origin
        xyz="-0.0003364 -0.0017872 0.003021"
        rpy="0 0 0" />
      <mass
        value="0.2517181" />
      <inertia
        ixx="0.0001076"
        ixy="2E-07"
        ixz="1E-07"
        iyy="8.35E-05"
        iyz="-1E-06"
        izz="8.85E-05" />
    </inertial>
    <visual>
      <origin
        xyz="0 0 0"
        rpy="0 0 0" />
      <geometry>
        <mesh
          filename="../meshes/head_pitch_link.STL" />
      </geometry>
      <material
        name="">
        <color
          rgba="0.75294 0.75294 0.75294 1" />
      </material>
    </visual>
    <collision>
      <origin
        xyz="0 0 0"
        rpy="0 0 0" />
      <geometry>
        <mesh
          filename="../meshes/head_pitch_link.STL" />
      </geometry>
    </collision>
  </link>
  <joint
    name="head_pitch_joint"
    type="fixed">  <!-- revolute -->
    <origin
      xyz="0.00033642 0.00013649 0.38114"
      rpy="0 0 0" />
    <parent
      link="body_m1_link" />
    <child
      link="head_pitch_link" />
    <axis
      xyz="0 -1 0" />
    <limit
      lower="-0.5"
      upper="0.5"
      effort="4.0"
      velocity="8" />
  </joint>
  <link
    name="head_yaw_link">
    <inertial>
      <origin
        xyz="0 0 0.0281898"
        rpy="0 0 0" />
      <mass
        value="0.191" />
      <inertia
        ixx="5.49E-05"
        ixy="0"
        ixz="0"
        iyy="5.52E-05"
        iyz="2E-07"
        izz="5.02E-05" />
    </inertial>
    <visual>
      <origin
        xyz="0 0 0"
        rpy="0 0 0" />
      <geometry>
        <mesh
          filename="../meshes/head_yaw_link.STL" />
      </geometry>
      <material
        name="">
        <color
          rgba="0.75294 0.75294 0.75294 1" />
      </material>
    </visual>
    <collision>
      <origin
        xyz="0 0 0"
        rpy="0 0 0" />
      <geometry>
        <mesh
          filename="../meshes/head_yaw_link.STL" />
      </geometry>
    </collision>
  </link>
  <joint
    name="head_yaw_joint"
    type="fixed">  <!-- revolute -->
    <origin
      xyz="-0.00033642 -0.00048649 0.032861"
      rpy="0 0 0" />
    <parent
      link="head_pitch_link" />
    <child
      link="head_yaw_link" />
    <axis
      xyz="0 0 1" />
    <limit
      lower="-1.0"
      upper="1.0"
      effort="4.0"
      velocity="8" />
  </joint>
  <link
    name="left_arm_m1_link">
    <inertial>
      <origin
        xyz="-0.000298 0.0505051 2.46E-05"
        rpy="0 0 0" />
      <mass
        value="0.4048768" />
      <inertia
        ixx="0.0002352"
        ixy="1E-07"
        ixz="2E-07"
        iyy="0.0001955"
        iyz="-1E-07"
        izz="0.0002688" />
    </inertial>
    <visual>
      <origin
        xyz="0 0 0"
        rpy="0 0 0" />
      <geometry>
        <mesh
          filename="../meshes/left_arm_m1_link.STL" />
      </geometry>
      <material
        name="">
        <color
          rgba="0.75294 0.75294 0.75294 1" />
      </material>
    </visual>
    <collision>
      <origin
        xyz="0 0 0"
        rpy="0 0 0" />
      <geometry>
        <mesh
          filename="../meshes/left_arm_m1_link.STL" />
      </geometry>
    </collision>
  </link>
  <joint
    name="left_arm_m1_joint"
    type="revolute">
    <origin
      xyz="0 0.12 0.339"
      rpy="0 0 0" />
    <parent
      link="body_m1_link" />
    <child
      link="left_arm_m1_link" />
    <axis
      xyz="0 -1 0" />
    <limit
      lower="-2.0"
      upper="2.0"
      effort="15"
      velocity="8" />
  </joint>
  <link
    name="left_arm_m2_link">
    <inertial>
      <origin
        xyz="-0.0256626 0.0918703 0"
        rpy="0 0 0" />
      <mass
        value="0.5485072" />
      <inertia
        ixx="0.000692"
        ixy="2.46E-05"
        ixz="-1.4E-06"
        iyy="0.0003351"
        iyz="0"
        izz="0.000816" />
    </inertial>
    <visual>
      <origin
        xyz="0 0 0"
        rpy="0 0 0" />
      <geometry>
        <mesh
          filename="../meshes/left_arm_m2_link.STL" />
      </geometry>
      <material
        name="">
        <color
          rgba="0.75294 0.75294 0.75294 1" />
      </material>
    </visual>
    <collision>
      <origin
        xyz="0 0 0"
        rpy="0 0 0" />
      <geometry>
        <mesh
          filename="../meshes/left_arm_m2_link.STL" />
      </geometry>
    </collision>
  </link>
  <joint
    name="left_arm_m2_joint"
    type="revolute">
    <origin
      xyz="0.0265 0.056 0"
      rpy="0 0 0" />
    <parent
      link="left_arm_m1_link" />
    <child
      link="left_arm_m2_link" />
    <axis
      xyz="-1 0 0" />
    <limit
      lower="-2"
      upper="2"
      effort="13"
      velocity="8" />
  </joint>
  <link
    name="left_arm_m3_link">
    <inertial>
      <origin
        xyz="-2.46E-05 0.0505051 -0.000298"
        rpy="0 0 0" />
      <mass
        value="0.4048768" />
      <inertia
        ixx="0.0002688"
        ixy="1E-07"
        ixz="-2E-07"
        iyy="0.0001955"
        iyz="1E-07"
        izz="0.0002352" />
    </inertial>
    <visual>
      <origin
        xyz="0 0 0"
        rpy="0 0 0" />
      <geometry>
        <mesh
          filename="../meshes/left_arm_m3_link.STL" />
      </geometry>
      <material
        name="">
        <color
          rgba="0.75294 0.75294 0.75294 1" />
      </material>
    </visual>
    <collision>
      <origin
        xyz="0 0 0"
        rpy="0 0 0" />
      <geometry>
        <mesh
          filename="../meshes/left_arm_m3_link.STL" />
      </geometry>
    </collision>
  </link>
  <joint
    name="left_arm_m3_joint"
    type="revolute">
    <origin
      xyz="-0.02615 0.121 0"
      rpy="0 0 0" />
    <parent
      link="left_arm_m2_link" />
    <child
      link="left_arm_m3_link" />
    <axis
      xyz="0 -1 0" />
    <limit
      lower="-1.8"
      upper="1.8"
      effort="13"
      velocity="8" />
  </joint>
  <link
    name="left_arm_m4_link">
    <inertial>
      <origin
        xyz="0 0.0918703 -0.0256626"
        rpy="0 0 0" />
      <mass
        value="0.5485072" />
      <inertia
        ixx="0.000816"
        ixy="0"
        ixz="1.4E-06"
        iyy="0.0003351"
        iyz="2.46E-05"
        izz="0.000692" />
    </inertial>
    <visual>
      <origin
        xyz="0 0 0"
        rpy="0 0 0" />
      <geometry>
        <mesh
          filename="../meshes/left_arm_m4_link.STL" />
      </geometry>
      <material
        name="">
        <color
          rgba="0.75294 0.75294 0.75294 1" />
      </material>
    </visual>
    <collision>
      <origin
        xyz="0 0 0"
        rpy="0 0 0" />
      <geometry>
        <mesh
          filename="../meshes/left_arm_m4_link.STL" />
      </geometry>
    </collision>
  </link>
  <joint
    name="left_arm_m4_joint"
    type="revolute">
    <origin
      xyz="0 0.056 0.0265"
      rpy="0 0 0" />
    <parent
      link="left_arm_m3_link" />
    <child
      link="left_arm_m4_link" />
    <axis
      xyz="0 0 -1" />
    <limit
      lower="-2.0"
      upper="2.0"
      effort="13"
      velocity="8" />
  </joint>
  <link
    name="left_arm_m5_link">
    <inertial>
      <origin
        xyz="-1.8053E-09 0.043849 1.8553E-06"
        rpy="0 0 0" />
      <mass
        value="0.0868808" />
      <inertia
        ixx="0.0002916"
        ixy="0"
        ixz="0"
        iyy="2.94E-05"
        iyz="0"
        izz="0.0002889" />
    </inertial>
    <visual>
      <origin
        xyz="0 0 0"
        rpy="0 0 0" />
      <geometry>
        <mesh
          filename="../meshes/left_arm_m5_link.STL" />
      </geometry>
      <material
        name="">
        <color
          rgba="0.75294 0.75294 0.75294 1" />
      </material>
    </visual>
    <collision>
      <origin
        xyz="0 0 0"
        rpy="0 0 0" />
      <geometry>
        <mesh
          filename="../meshes/left_arm_m5_link.STL" />
      </geometry>
    </collision>
  </link>
  <joint
    name="left_arm_m5_joint"
    type="revolute">
    <origin
      xyz="0 0.135 -0.02615"
      rpy="0 0 0" />
    <parent
      link="left_arm_m4_link" />
    <child
      link="left_arm_m5_link" />
    <axis
      xyz="0 -1 0" />
    <limit
      lower="-1.8"
      upper="1.8"
      effort="13"
      velocity="8" />
  </joint>
  <link
    name="left_arm_m6_link">
    <inertial>
      <origin
        xyz="0.025571 -0.00011967 -1.0933E-09"
        rpy="0 0 0" />
      <mass
        value="0.0012644" />
      <inertia
        ixx="0.00001"
        ixy="0.00000"
        ixz="0.00000"
        iyy="0.00001"
        iyz="0.00000"
        izz="0.00001" />
    </inertial>
    <visual>
      <origin
        xyz="0 0 0"
        rpy="0 0 0" />
      <geometry>
        <mesh
          filename="../meshes/left_arm_m6_link.STL" />
      </geometry>
      <material
        name="">
        <color
          rgba="0.65098 0.61961 0.58824 1" />
      </material>
    </visual>
    <collision>
      <origin
        xyz="0 0 0"
        rpy="0 0 0" />
      <geometry>
        <mesh
          filename="../meshes/left_arm_m6_link.STL" />
      </geometry>
    </collision>
  </link>
  <joint
    name="left_arm_m6_joint"
    type="revolute">  <!-- revolute -->
    <origin
      xyz="0 0.13212 0"
      rpy="0 0 0" />
    <parent
      link="left_arm_m5_link" />
    <child
      link="left_arm_m6_link" />
    <axis
      xyz="-1 0 0" />
    <limit
      lower="-1.0"
      upper="1.0"
      effort="1"
      velocity="8" />
  </joint>
  <link
    name="right_arm_m1_link">
    <inertial>
      <origin
        xyz="-0.000298 -0.0505051 -2.46E-05"
        rpy="0 0 0" />
      <mass
        value="0.4048768" />
      <inertia
        ixx="0.0002352"
        ixy="-1E-07"
        ixz="-2E-07"
        iyy="0.0001955"
        iyz="-1E-07"
        izz="0.0002688" />
    </inertial>
    <visual>
      <origin
        xyz="0 0 0"
        rpy="0 0 0" />
      <geometry>
        <mesh
          filename="../meshes/right_arm_m1_link.STL" />
      </geometry>
      <material
        name="">
        <color
          rgba="0.75294 0.75294 0.75294 1" />
      </material>
    </visual>
    <collision>
      <origin
        xyz="0 0 0"
        rpy="0 0 0" />
      <geometry>
        <mesh
          filename="../meshes/right_arm_m1_link.STL" />
      </geometry>
    </collision>
  </link>
  <joint
    name="right_arm_m1_joint"
    type="revolute">
    <origin
      xyz="0 -0.12 0.339"
      rpy="0 0 0" />
    <parent
      link="body_m1_link" />
    <child
      link="right_arm_m1_link" />
    <axis
      xyz="0 1 0" />
    <limit
      lower="-2.0"
      upper="2.0"
      effort="15"
      velocity="8" />
  </joint>
  <link
    name="right_arm_m2_link">
    <inertial>
      <origin
        xyz="-0.0256626 -0.0918703 0"
        rpy="0 0 0" />
      <mass
        value="0.5485072" />
      <inertia
        ixx="0.000692"
        ixy="-2.46E-05"
        ixz="1.4E-06"
        iyy="0.0003351"
        iyz="0"
        izz="0.000816" />
    </inertial>
    <visual>
      <origin
        xyz="0 0 0"
        rpy="0 0 0" />
      <geometry>
        <mesh
          filename="../meshes/right_arm_m2_link.STL" />
      </geometry>
      <material
        name="">
        <color
          rgba="0.75294 0.75294 0.75294 1" />
      </material>
    </visual>
    <collision>
      <origin
        xyz="0 0 0"
        rpy="0 0 0" />
      <geometry>
        <mesh
          filename="../meshes/right_arm_m2_link.STL" />
      </geometry>
    </collision>
  </link>
  <joint
    name="right_arm_m2_joint"
    type="revolute">
    <origin
      xyz="0.0265 -0.056 0"
      rpy="0 0 0" />
    <parent
      link="right_arm_m1_link" />
    <child
      link="right_arm_m2_link" />
    <axis
      xyz="-1 0 0" />
    <limit
      lower="-2"
      upper="2"
      effort="13"
      velocity="8" />
  </joint>
  <link
    name="right_arm_m3_link">
    <inertial>
      <origin
        xyz="2.46E-05 -0.0505051 -0.000298"
        rpy="0 0 0" />
      <mass
        value="0.4048768" />
      <inertia
        ixx="0.0002688"
        ixy="1E-07"
        ixz="2E-07"
        iyy="0.0001955"
        iyz="-1E-07"
        izz="0.0002352" />
    </inertial>
    <visual>
      <origin
        xyz="0 0 0"
        rpy="0 0 0" />
      <geometry>
        <mesh
          filename="../meshes/right_arm_m3_link.STL" />
      </geometry>
      <material
        name="">
        <color
          rgba="0.75294 0.75294 0.75294 1" />
      </material>
    </visual>
    <collision>
      <origin
        xyz="0 0 0"
        rpy="0 0 0" />
      <geometry>
        <mesh
          filename="../meshes/right_arm_m3_link.STL" />
      </geometry>
    </collision>
  </link>
  <joint
    name="right_arm_m3_joint"
    type="revolute">
    <origin
      xyz="-0.02615 -0.121 0"
      rpy="0 0 0" />
    <parent
      link="right_arm_m2_link" />
    <child
      link="right_arm_m3_link" />
    <axis
      xyz="0 1 0" />
    <limit
      lower="-1.8"
      upper="1.8"
      effort="13"
      velocity="8" />
  </joint>
  <link
    name="right_arm_m4_link">
    <inertial>
      <origin
        xyz="0 -0.0918703 -0.0256626"
        rpy="0 0 0" />
      <mass
        value="0.5485072" />
      <inertia
        ixx="0.000816"
        ixy="0"
        ixz="-1.4E-06"
        iyy="0.0003351"
        iyz="-2.46E-05"
        izz="0.000692" />
    </inertial>
    <visual>
      <origin
        xyz="0 0 0"
        rpy="0 0 0" />
      <geometry>
        <mesh
          filename="../meshes/right_arm_m4_link.STL" />
      </geometry>
      <material
        name="">
        <color
          rgba="0.75294 0.75294 0.75294 1" />
      </material>
    </visual>
    <collision>
      <origin
        xyz="0 0 0"
        rpy="0 0 0" />
      <geometry>
        <mesh
          filename="../meshes/right_arm_m4_link.STL" />
      </geometry>
    </collision>
  </link>
  <joint
    name="right_arm_m4_joint"
    type="revolute">
    <origin
      xyz="0 -0.056 0.0265"
      rpy="0 0 0" />
    <parent
      link="right_arm_m3_link" />
    <child
      link="right_arm_m4_link" />
    <axis
      xyz="0 0 -1" />
    <limit
      lower="-2.0"
      upper="2.0"
      effort="13"
      velocity="8" />
  </joint>
  <link
    name="right_arm_m5_link">
    <inertial>
      <origin
        xyz="0 -0.0438485 1.9E-06"
        rpy="0 0 0" />
      <mass
        value="0.0868808" />
      <inertia
        ixx="0.0002916"
        ixy="0"
        ixz="0"
        iyy="2.94E-05"
        iyz="0"
        izz="0.0002889" />
    </inertial>
    <visual>
      <origin
        xyz="0 0 0"
        rpy="0 0 0" />
      <geometry>
        <mesh
          filename="../meshes/right_arm_m5_link.STL" />
      </geometry>
      <material
        name="">
        <color
          rgba="0.75294 0.75294 0.75294 1" />
      </material>
    </visual>
    <collision>
      <origin
        xyz="0 0 0"
        rpy="0 0 0" />
      <geometry>
        <mesh
          filename="../meshes/right_arm_m5_link.STL" />
      </geometry>
    </collision>
  </link>
  <joint
    name="right_arm_m5_joint"
    type="revolute">
    <origin
      xyz="0 -0.135 -0.02615"
      rpy="0 0 0" />
    <parent
      link="right_arm_m4_link" />
    <child
      link="right_arm_m5_link" />
    <axis
      xyz="0 1 0" />
    <limit
      lower="-1.8"
      upper="1.8"
      effort="13"
      velocity="8" />
  </joint>
  <link
    name="right_arm_m6_link">
    <inertial>
      <origin
        xyz="0.0255706 0.0001197 0"
        rpy="0 0 0" />
      <mass
        value="0.0012644" />
      <inertia
        ixx="0.00001"
        ixy="0.00000"
        ixz="0.00000"
        iyy="0.00001"
        iyz="0.00000"
        izz="0.00001" />
    </inertial>
    <visual>
      <origin
        xyz="0 0 0"
        rpy="0 0 0" />
      <geometry>
        <mesh
          filename="../meshes/right_arm_m6_link.STL" />
      </geometry>
      <material
        name="">
        <color
          rgba="0.65098 0.61961 0.58824 1" />
      </material>
    </visual>
    <collision>
      <origin
        xyz="0 0 0"
        rpy="0 0 0" />
      <geometry>
        <mesh
          filename="../meshes/right_arm_m6_link.STL" />
      </geometry>
    </collision>
  </link>
  <joint
    name="right_arm_m6_joint"
    type="revolute">  <!-- revolute -->
    <origin
      xyz="0 -0.13212 0"
      rpy="0 0 0" />
    <parent
      link="right_arm_m5_link" />
    <child
      link="right_arm_m6_link" />
    <axis
      xyz="-1 0 0" />
    <limit
      lower="-1."
      upper="1.0"
      effort="1"
      velocity="8" />
  </joint>
  <link name="left_leg_toe_link">
  </link>
  <joint name="left_leg_toe_joint" type="fixed">
    <origin
      xyz="0.13 0 -0.05"
      rpy="0 0 0" />
    <parent
      link="left_leg_ankle_link" />
    <child
      link="left_leg_toe_link" />
  </joint>
  <link name="right_leg_toe_link">
  </link>
  <joint name="right_leg_toe_joint" type="fixed">
    <origin
      xyz="0.13 0 -0.05"
      rpy="0 0 0" />
    <parent
      link="right_leg_ankle_link" />
    <child
      link="right_leg_toe_link" />
  </joint>
  <link name="left_leg_heel_link">
  </link>
  <joint name="left_leg_heel_joint" type="fixed">
    <origin
      xyz="-0.05 0 -0.05"
      rpy="0 0 0" />
    <parent
      link="left_leg_ankle_link" />
    <child
      link="left_leg_heel_link" />
  </joint>
  <link name="right_leg_heel_link">
  </link>
  <joint name="right_leg_heel_joint" type="fixed">
    <origin
      xyz="-0.05 0 -0.05"
      rpy="0 0 0" />
    <parent
      link="right_leg_ankle_link" />
    <child
      link="right_leg_heel_link" />
  </joint>
</robot>